Workbook

Sheet Project Data
A1: :candidates:fullname | B1: :candidates:positions*1:company | C1: :candidates:latestPositions*1:title | D1: :candidates:positions*1:location | E1: :candidates:pipelineTags*1 | F1: :candidates:custom:boYK | G1: :candidates:notes:latest:researcher:tag:date
A2: Name | B2: Current Company | C2: Current Role | D2: Location | E2: Pipeline Tag | F2: Gender | G2: Notes
A3: ← Tool populates data from this row downward. Any number of rows.

Sheet _Pivot
A1: _tag | B1: _count | C1: _pct
A2: =IFERROR(INDEX('Project Data'!$E$3:$E$10000,MATCH(0,COUNTIF($A$1:A1,'Project Data'!$E$3:$E$10000)+(('Project Data'!$E$3:$E$10000)=""),0)),"") | B2: =IF(A2="","",COUNTIF('Project Data'!$E$3:$E$10000,A2)) | C2: =IFERROR(B2/SUM($B$2:$B$31),"")
A3: =IFERROR(INDEX('Project Data'!$E$3:$E$10000,MATCH(0,COUNTIF($A$1:A2,'Project Data'!$E$3:$E$10000)+(('Project Data'!$E$3:$E$10000)=""),0)),"") | B3: =IF(A3="","",COUNTIF('Project Data'!$E$3:$E$10000,A3)) | C3: =IFERROR(B3/SUM($B$2:$B$31),"")
A4: =IFERROR(INDEX('Project Data'!$E$3:$E$10000,MATCH(0,COUNTIF($A$1:A3,'Project Data'!$E$3:$E$10000)+(('Project Data'!$E$3:$E$10000)=""),0)),"") | B4: =IF(A4="","",COUNTIF('Project Data'!$E$3:$E$10000,A4)) | C4: =IFERROR(B4/SUM($B$2:$B$31),"")
A5: =IFERROR(INDEX('Project Data'!$E$3:$E$10000,MATCH(0,COUNTIF($A$1:A4,'Project Data'!$E$3:$E$10000)+(('Project Data'!$E$3:$E$10000)=""),0)),"") | B5: =IF(A5="","",COUNTIF('Project Data'!$E$3:$E$10000,A5)) | C5: =IFERROR(B5/SUM($B$2:$B$31),"")
A6: =IFERROR(INDEX('Project Data'!$E$3:$E$10000,MATCH(0,COUNTIF($A$1:A5,'Project Data'!$E$3:$E$10000)+(('Project Data'!$E$3:$E$10000)=""),0)),"") | B6: =IF(A6="","",COUNTIF('Project Data'!$E$3:$E$10000,A6)) | C6: =IFERROR(B6/SUM($B$2:$B$31),"")
A7: =IFERROR(INDEX('Project Data'!$E$3:$E$10000,MATCH(0,COUNTIF($A$1:A6,'Project Data'!$E$3:$E$10000)+(('Project Data'!$E$3:$E$10000)=""),0)),"") | B7: =IF(A7="","",COUNTIF('Project Data'!$E$3:$E$10000,A7)) | C7: =IFERROR(B7/SUM($B$2:$B$31),"")
A8: =IFERROR(INDEX('Project Data'!$E$3:$E$10000,MATCH(0,COUNTIF($A$1:A7,'Project Data'!$E$3:$E$10000)+(('Project Data'!$E$3:$E$10000)=""),0)),"") | B8: =IF(A8="","",COUNTIF('Project Data'!$E$3:$E$10000,A8)) | C8: =IFERROR(B8/SUM($B$2:$B$31),"")
A9: =IFERROR(INDEX('Project Data'!$E$3:$E$10000,MATCH(0,COUNTIF($A$1:A8,'Project Data'!$E$3:$E$10000)+(('Project Data'!$E$3:$E$10000)=""),0)),"") | B9: =IF(A9="","",COUNTIF('Project Data'!$E$3:$E$10000,A9)) | C9: =IFERROR(B9/SUM($B$2:$B$31),"")
A10: =IFERROR(INDEX('Project Data'!$E$3:$E$10000,MATCH(0,COUNTIF($A$1:A9,'Project Data'!$E$3:$E$10000)+(('Project Data'!$E$3:$E$10000)=""),0)),"") | B10: =IF(A10="","",COUNTIF('Project Data'!$E$3:$E$10000,A10)) | C10: =IFERROR(B10/SUM($B$2:$B$31),"")
A11: =IFERROR(INDEX('Project Data'!$E$3:$E$10000,MATCH(0,COUNTIF($A$1:A10,'Project Data'!$E$3:$E$10000)+(('Project Data'!$E$3:$E$10000)=""),0)),"") | B11: =IF(A11="","",COUNTIF('Project Data'!$E$3:$E$10000,A11)) | C11: =IFERROR(B11/SUM($B$2:$B$31),"")
A12: =IFERROR(INDEX('Project Data'!$E$3:$E$10000,MATCH(0,COUNTIF($A$1:A11,'Project Data'!$E$3:$E$10000)+(('Project Data'!$E$3:$E$10000)=""),0)),"") | B12: =IF(A12="","",COUNTIF('Project Data'!$E$3:$E$10000,A12)) | C12: =IFERROR(B12/SUM($B$2:$B$31),"")
A13: =IFERROR(INDEX('Project Data'!$E$3:$E$10000,MATCH(0,COUNTIF($A$1:A12,'Project Data'!$E$3:$E$10000)+(('Project Data'!$E$3:$E$10000)=""),0)),"") | B13: =IF(A13="","",COUNTIF('Project Data'!$E$3:$E$10000,A13)) | C13: =IFERROR(B13/SUM($B$2:$B$31),"")
... A31: =IFERROR(INDEX('Project Data'!$E$3:$E$10000,MATCH(0,COUNTIF($A$1:A30,'Project Data'!$E$3:$E$10000)+(('Project Data'!$E$3:$E$10000)=""),0)),"") | B31: =IF(A31="","",COUNTIF('Project Data'!$E$3:$E$10000,A31)) | C31: =IFERROR(B31/SUM($B$2:$B$31),"")

Sheet Dashboard
A1: #VALUE!
A2: PROJECT REPORT · {{project_name}} · {{report_date}}
A5: Total Candidates | C5: Unique Tags | E5: In Interview | G5: Offers Made | I5: Placed
A6: =COUNTA('Project Data'!$A$3:$A$10000)-COUNTBLANK('Project Data'!$A$3:$A$10000) -> -9996 | C6: =COUNTIF(_Pivot!A2:A31,"?*") -> 0 | E6: =COUNTIF('Project Data'!$E$3:$E$10000,"Interview") -> 0 | G6: =COUNTIF('Project Data'!$E$3:$E$10000,"Offer") -> 0 | I6: =COUNTIF('Project Data'!$E$3:$E$10000,"Placed") -> 0
A11: PIPELINE BREAKDOWN | F11: PROJECT DETAILS
A12: Pipeline Tag | B12: Count | C12: % of Total | D12: Distribution | F12: Project Name | H12: {{project_name}}
A13: =IF(_Pivot!A2="","",_Pivot!A2) | B13: =IF(A13="","",_Pivot!B2) | C13: =IF(A13="","",_Pivot!C2) | D13: =IF(A13="","",IFERROR(REPT("█",ROUND(C13*25,0)),"")) | F13: Assignment Type | H13: {{assignment_type}}
A14: =IF(_Pivot!A3="","",_Pivot!A3) | B14: =IF(A14="","",_Pivot!B3) | C14: =IF(A14="","",_Pivot!C3) | D14: =IF(A14="","",IFERROR(REPT("█",ROUND(C14*25,0)),"")) | F14: Client | H14: {{client_name}}
A15: =IF(_Pivot!A4="","",_Pivot!A4) | B15: =IF(A15="","",_Pivot!B4) | C15: =IF(A15="","",_Pivot!C4) | D15: =IF(A15="","",IFERROR(REPT("█",ROUND(C15*25,0)),"")) | F15: Lead Consultant | H15: {{lead_consultant}}
A16: =IF(_Pivot!A5="","",_Pivot!A5) | B16: =IF(A16="","",_Pivot!B5) | C16: =IF(A16="","",_Pivot!C5) | D16: =IF(A16="","",IFERROR(REPT("█",ROUND(C16*25,0)),"")) | F16: Researcher | H16: {{researcher_name}}
A17: =IF(_Pivot!A6="","",_Pivot!A6) | B17: =IF(A17="","",_Pivot!B6) | C17: =IF(A17="","",_Pivot!C6) | D17: =IF(A17="","",IFERROR(REPT("█",ROUND(C17*25,0)),"")) | F17: Date Created | H17: {{date_created}}
A18: =IF(_Pivot!A7="","",_Pivot!A7) | B18: =IF(A18="","",_Pivot!B7) | C18: =IF(A18="","",_Pivot!C7) | D18: =IF(A18="","",IFERROR(REPT("█",ROUND(C18*25,0)),"")) | F18: Report Date | H18: {{report_date}}
A19: =IF(_Pivot!A8="","",_Pivot!A8) | B19: =IF(A19="","",_Pivot!B8) | C19: =IF(A19="","",_Pivot!C8) | D19: =IF(A19="","",IFERROR(REPT("█",ROUND(C19*25,0)),"")) | F19: Status | H19: {{project_status}}
A20: =IF(_Pivot!A9="","",_Pivot!A9) | B20: =IF(A20="","",_Pivot!B9) | C20: =IF(A20="","",_Pivot!C9) | D20: =IF(A20="","",IFERROR(REPT("█",ROUND(C20*25,0)),"")) | F20: Practice | H20: {{practice_area}}
A21: =IF(_Pivot!A10="","",_Pivot!A10) | B21: =IF(A21="","",_Pivot!B10) | C21: =IF(A21="","",_Pivot!C10) | D21: =IF(A21="","",IFERROR(REPT("█",ROUND(C21*25,0)),"")) | F21: Geography | H21: {{geography}}
A22: =IF(_Pivot!A11="","",_Pivot!A11) | B22: =IF(A22="","",_Pivot!B11) | C22: =IF(A22="","",_Pivot!C11) | D22: =IF(A22="","",IFERROR(REPT("█",ROUND(C22*25,0)),""))
A23: =IF(_Pivot!A12="","",_Pivot!A12) | B23: =IF(A23="","",_Pivot!B12) | C23: =IF(A23="","",_Pivot!C12) | D23: =IF(A23="","",IFERROR(REPT("█",ROUND(C23*25,0)),""))
A24: =IF(_Pivot!A13="","",_Pivot!A13) | B24: =IF(A24="","",_Pivot!B13) | C24: =IF(A24="","",_Pivot!C13) | D24: =IF(A24="","",IFERROR(REPT("█",ROUND(C24*25,0)),""))
A25: =IF(_Pivot!A14="","",_Pivot!A14) | B25: =IF(A25="","",_Pivot!B14) | C25: =IF(A25="","",_Pivot!C14) | D25: =IF(A25="","",IFERROR(REPT("█",ROUND(C25*25,0)),""))
A26: =IF(_Pivot!A15="","",_Pivot!A15) | B26: =IF(A26="","",_Pivot!B15) | C26: =IF(A26="","",_Pivot!C15) | D26: =IF(A26="","",IFERROR(REPT("█",ROUND(C26*25,0)),"")) | F26: TOP LOCATIONS
A27: =IF(_Pivot!A16="","",_Pivot!A16) | B27: =IF(A27="","",_Pivot!B16) | C27: =IF(A27="","",_Pivot!C16) | D27: =IF(A27="","",IFERROR(REPT("█",ROUND(C27*25,0)),"")) | F27: Location | I27: Count | J27: %
A28: =IF(_Pivot!A17="","",_Pivot!A17) | B28: =IF(A28="","",_Pivot!B17) | C28: =IF(A28="","",_Pivot!C17) | D28: =IF(A28="","",IFERROR(REPT("█",ROUND(C28*25,0)),"")) | F28: {{top_location_1}} | I28: =IF(F28="","",COUNTIF('Project Data'!$D$3:$D$10000,F28)) -> 0 | J28: =IFERROR(I28/SUM(I28:I35),"")
A29: =IF(_Pivot!A18="","",_Pivot!A18) | B29: =IF(A29="","",_Pivot!B18) | C29: =IF(A29="","",_Pivot!C18) | D29: =IF(A29="","",IFERROR(REPT("█",ROUND(C29*25,0)),"")) | F29: {{top_location_2}} | I29: =IF(F29="","",COUNTIF('Project Data'!$D$3:$D$10000,F29)) -> 0 | J29: =IFERROR(I29/SUM(I28:I35),"")
A30: =IF(_Pivot!A19="","",_Pivot!A19) | B30: =IF(A30="","",_Pivot!B19) | C30: =IF(A30="","",_Pivot!C19) | D30: =IF(A30="","",IFERROR(REPT("█",ROUND(C30*25,0)),"")) | F30: {{top_location_3}} | I30: =IF(F30="","",COUNTIF('Project Data'!$D$3:$D$10000,F30)) -> 0 | J30: =IFERROR(I30/SUM(I28:I35),"")
A31: =IF(_Pivot!A20="","",_Pivot!A20) | B31: =IF(A31="","",_Pivot!B20) | C31: =IF(A31="","",_Pivot!C20) | D31: =IF(A31="","",IFERROR(REPT("█",ROUND(C31*25,0)),"")) | F31: {{top_location_4}} | I31: =IF(F31="","",COUNTIF('Project Data'!$D$3:$D$10000,F31)) -> 0 | J31: =IFERROR(I31/SUM(I28:I35),"")
A32: =IF(_Pivot!A21="","",_Pivot!A21) | B32: =IF(A32="","",_Pivot!B21) | C32: =IF(A32="","",_Pivot!C21) | D32: =IF(A32="","",IFERROR(REPT("█",ROUND(C32*25,0)),"")) | F32: {{top_location_5}} | I32: =IF(F32="","",COUNTIF('Project Data'!$D$3:$D$10000,F32)) -> 0 | J32: =IFERROR(I32/SUM(I28:I35),"")
A33: =IF(_Pivot!A22="","",_Pivot!A22) | B33: =IF(A33="","",_Pivot!B22) | C33: =IF(A33="","",_Pivot!C22) | D33: =IF(A33="","",IFERROR(REPT("█",ROUND(C33*25,0)),"")) | F33: {{top_location_6}} | I33: =IF(F33="","",COUNTIF('Project Data'!$D$3:$D$10000,F33)) -> 0 | J33: =IFERROR(I33/SUM(I28:I35),"")
A34: =IF(_Pivot!A23="","",_Pivot!A23) | B34: =IF(A34="","",_Pivot!B23) | C34: =IF(A34="","",_Pivot!C23) | D34: =IF(A34="","",IFERROR(REPT("█",ROUND(C34*25,0)),"")) | F34: {{top_location_7}} | I34: =IF(F34="","",COUNTIF('Project Data'!$D$3:$D$10000,F34)) -> 0 | J34: =IFERROR(I34/SUM(I28:I35),"")
A35: =IF(_Pivot!A24="","",_Pivot!A24) | B35: =IF(A35="","",_Pivot!B24) | C35: =IF(A35="","",_Pivot!C24) | D35: =IF(A35="","",IFERROR(REPT("█",ROUND(C35*25,0)),"")) | F35: {{top_location_8}} | I35: =IF(F35="","",COUNTIF('Project Data'!$D$3:$D$10000,F35)) -> 0 | J35: =IFERROR(I35/SUM(I28:I35),"")
A36: =IF(_Pivot!A25="","",_Pivot!A25) | B36: =IF(A36="","",_Pivot!B25) | C36: =IF(A36="","",_Pivot!C25) | D36: =IF(A36="","",IFERROR(REPT("█",ROUND(C36*25,0)),""))
A37: =IF(_Pivot!A26="","",_Pivot!A26) | B37: =IF(A37="","",_Pivot!B26) | C37: =IF(A37="","",_Pivot!C26) | D37: =IF(A37="","",IFERROR(REPT("█",ROUND(C37*25,0)),""))
A38: =IF(_Pivot!A27="","",_Pivot!A27) | B38: =IF(A38="","",_Pivot!B27) | C38: =IF(A38="","",_Pivot!C27) | D38: =IF(A38="","",IFERROR(REPT("█",ROUND(C38*25,0)),""))
A39: =IF(_Pivot!A28="","",_Pivot!A28) | B39: =IF(A39="","",_Pivot!B28) | C39: =IF(A39="","",_Pivot!C28) | D39: =IF(A39="","",IFERROR(REPT("█",ROUND(C39*25,0)),""))
A40: =IF(_Pivot!A29="","",_Pivot!A29) | B40: =IF(A40="","",_Pivot!B29) | C40: =IF(A40="","",_Pivot!C29) | D40: =IF(A40="","",IFERROR(REPT("█",ROUND(C40*25,0)),""))
A41: =IF(_Pivot!A30="","",_Pivot!A30) | B41: =IF(A41="","",_Pivot!B30) | C41: =IF(A41="","",_Pivot!C30) | D41: =IF(A41="","",IFERROR(REPT("█",ROUND(C41*25,0)),""))
A42: =IF(_Pivot!A31="","",_Pivot!A31) | B42: =IF(A42="","",_Pivot!B31) | C42: =IF(A42="","",_Pivot!C31) | D42: =IF(A42="","",IFERROR(REPT("█",ROUND(C42*25,0)),""))
A43: TOTAL | B43: =COUNTA('Project Data'!$A$3:$A$10000)-COUNTBLANK('Project Data'!$A$3:$A$10000) -> -9996 | C43: =IFERROR(SUM(C13:C42),"") -> 0
A45: GENDER SPLIT
A46: Gender | B46: Count | C46: % | D46: Bar
A47: Male | B47: =COUNTIF('Project Data'!$F$3:$F$10000,A47) -> 0 | C47: =IFERROR(B47/SUM(B47:B50),0) -> 0 | D47: =IFERROR(REPT("█",ROUND(C47*20,0)),"")
...

Sheet Template Guide
A1: TEMPLATE GUIDE — Sheffield Haworth Project Report
A2: ARCHITECTURE
A3: Project Data | B3: Tool writes rows from row 3 downward. No row limit. Row 1 (hidden) = Ezekia API keys. Row 2 = display headers.
A4: _Pivot (hidden) | B4: Extracts unique pipeline tags from Project Data col E using array formulas. Supports up to 30 unique tags. Dashboard reads from here.
A5: Dashboard | B5: Reads _Pivot for pipeline breakdown (dynamic, no hardcoded tags). All counts/% are formulas.
A7: TOOL RESPONSIBILITIES
A8: 1. Candidate rows | B8: Write data into Project Data from row 3. Any number of rows.
A9: 2. Metadata tokens | B9: Replace {{mustache}} placeholders in Dashboard metadata panel.
A10: 3. Top locations | B10: Write top-N location names into Dashboard F28:F35. Counts auto-calculate.
A12: PIPELINE TAGS
A13: Dynamic | B13: Tags are NOT hardcoded. _Pivot extracts whatever unique values exist in col E of Project Data.
A14: Up to 30 unique tags | B14: Dashboard pipeline table has 30 rows — blank rows hide automatically when tag is empty.
